Workbook

Sheet Raw data
A1: Product | B1: Current price | C1: old price | D1: Discount | E1: Review | F1: Ratingd
A2: 115 Piece Set Of Multifunctional Precision Screwdrivers | B2: KSh 950 | C2: KSh 1,525 | D2: 0.38 | E2: -2 | F2: 4.5 out of 5
A3: Metal Decorative Hooks Key Hangers Entryway Wall Hooks Towel Hooks - Home | B3: KSh 527 | C3: KSh 999 | D3: 0.47 | E3: -14 | F3: 4.1 out of 5
A4: Portable Mini Cordless Car Vacuum Cleaner - Blue | B4: KSh 2,199 | C4: KSh 2,923 | D4: 0.25 | E4: -24 | F4: 4.6 out of 5
A5: Weighing Scale Digital Bathroom Body Fat Scale USB-Black | B5: KSh 1,580 | C5: KSh 2,499 | D5: 0.37 | E5: -7 | F5: 4.7 out of 5
A6: Portable Home Small Air Humidifier 3-Speed Fan - Green | B6: KSh 1,740 | C6: KSh 2,356 | D6: 0.26 | E6: -5 | F6: 4.8 out of 5
A7: 220V 60W Electric Soldering Iron Kits With Tools, Tips, And Multimeter | B7: KSh 2,999 | C7: KSh 3,290 | D7: 0.09 | E7: -15 | F7: 4 out of 5
A8: 137 Pieces Cake Decorating Tool Set Baking Supplies | B8: KSh 2,319 | C8: KSh 3,032 | D8: 0.24 | E8: -55 | F8: 4.6 out of 5
A9: Desk Foldable Fan Adjustable Fan Strong Wind 3 Gear Usb | B9: KSh 988 | C9: KSh 1,580 | D9: 0.37 | E9: -2 | F9: 4 out of 5
A10: LASA FOLDING TABLE SERVING STAND | B10: KSh 1,274 | C10: KSh 2,800 | D10: 0.55 | E10: -5 | F10: 4.8 out of 5
A11: 13 In 1 Home Repair Tools Box Kit Set | B11: KSh 1,600 | C11: KSh 2,929 | D11: 0.45 | E11: -5 | F11: 3.8 out of 5
A12: Genebre 115 In 1 Screwdriver Repairing Tool Set For IPhone Cellphone Hand Tool | B12: KSh 799 | C12: KSh 999 | D12: 0.2 | E12: -12 | F12: 4.1 out of 5
A13: 100 Pcs Crochet Hook Tool Set Knitting Hook Set With Box | B13: KSh 990 | C13: KSh 1,500 | D13: 0.34 | E13: -39 | F13: 4.7 out of 5
... A22: 3PCS Single Head Knitting Crochet Sweater Needle Set | B22: KSh 38 | C22: KSh 80 | D22: 0.53 | E22: -13 | F22: 3.3 out of 5
A23: 4pcs Bathroom/Kitchen Towel Rack,Roll Paper Holder,Towel Bars,Hook | B23: KSh 1,860 | C23: KSh 3,220 | D23: 0.42
A24: LED Romantic Spaceship Starry Sky Projector,Children's Bedroom Night Light-Blue | B24: KSh 880 | C24: KSh 1,350 | D24: 0.35 | E24: -6 | F24: 4 out of 5
A25: Foldable Overbed Table/Desk | B25: KSh 1,650 | C25: KSh 2,150 | D25: 0.23 | E25: -14 | F25: 4.4 out of 5
A26: LASA 3 Tier Bamboo Shoe Bench Storage Shelf | B26: KSh 2,048 | C26: KSh 4,500 | D26: 0.54 | E26: -7 | F26: 4.3 out of 5
A27: Electronic Digital Display Vernier Caliper | B27: KSh 420 | C27: KSh 647 | D27: 0.35 | E27: -49 | F27: 4.6 out of 5
A28: Portable Wardrobe Nonwoven With 3 Hanging Rods And 6 Storage Shelves | B28: KSh 2,880 | C28: KSh 3,520 | D28: 0.18 | E28: -12 | F28: 3.8 out of 5
A29: 12 Litre Black Insulated Lunch Box | B29: KSh 1,350 | C29: KSh 1,990 | D29: 0.32 | E29: -13 | F29: 3.8 out of 5
A30: 52 Pieces Cake Decorating Tool Set Gift Kit Baking Supplies | B30: KSh 1,758 | C30: KSh 2,499 | D30: 0.3 | E30: -20 | F30: 4.1 out of 5
A31: MultiFunctional Storage Rack Multi-layer Bookshelf | B31: KSh 2,200 | C31: KSh 4,080 | D31: 0.46
A32: Exfoliate And Exfoliate Face Towel - Black | B32: KSh 185 | C32: KSh 382 | D32: 0.52 | E32: -9 | F32: 4.3 out of 5
A33: 12 Litre Insulated Lunch Box Grey | B33: KSh 980 | C33: KSh 1,490 | D33: 0.34 | E33: -12 | F33: 4.7 out of 5
A34: LED Eye Protection Desk Lamp , Study, Reading, USB Fan - Double Pen Holder | B34: KSh 1,820 | C34: KSh 3,490 | D34: 0.48 | E34: -9 | F34: 4.3 out of 5
A35: 53Pcs/Set Yarn Knitting Crochet Hooks With Bag - Fortune Cat | B35: KSh 1,940 | C35: KSh 2,650 | D35: 0.27 | E35: -20 | F35: 4.7 out of 5
A36: 53 Pieces/Set Yarn Knitting Crochet Hooks With Bag - Pansies | B36: KSh 1,980 | C36: KSh 2,699 | D36: 0.27 | E36: -32 | F36: 4.5 out of 5
A37: DIY File Folder, Office Drawer File Holder, Pen Holder, Desktop Storage Rack | B37: KSh 1,620 | C37: KSh 2,690 | D37: 0.4 | E37: -1 | F37: 5 out of 5
A38: Classic Black Cat Cotton Hemp Pillow Case For Home Car | B38: KSh 171 | C38: KSh 360 | D38: 0.53 | E38: -2 | F38: 5 out of 5
A39: Punch-free Great Load Bearing Bathroom Storage Rack Wall Shelf-White | B39: KSh 389 | C39: KSh 656 | D39: 0.41 | E39: -36 | F39: 4.3 out of 5
A40: 1/2/3 Seater Elastic Sofa Cover,Living Room/Home Decor Chair Cover-Grey | B40: KSh 1,620 - KSh 1,980 | C40: KSh 2,200 - KSh 3,200 | D40: 0.38 | E40: -2 | F40: 4.5 out of 5
A41: LASA Stainless Steel Double Wall Mount Soap Dispenser - 500ml | B41: KSh 2,750 | C41: KSh 4,471 | D41: 0.38
A42: 4M Float Switch Water Level Controller -Water Tank | B42: KSh 475 | C42: KSh 931 | D42: 0.49
A43: Modern Sofa Throw Pillow Cover-45x45cm-Blue&Red | B43: KSh 238 | C43: KSh 476 | D43: 0.5
A44: Balloon Insert, Birthday Party Balloon Set, PU Leather | B44: KSh 610 | C44: KSh 1,060 | D44: 0.42
A45: Balloon Insert, Birthday Party Balloon Set, PU Leather | B45: KSh 610 | C45: KSh 1,060 | D45: 0.42
A46: Shower Cap Wide Elastic Band Cover Reusable Bashroom Cap | B46: KSh 2,132 | C46: KSh 2,169 | D46: 0.02
A47: Christmas Elk Fence Yard Lawn Decorations Cute For Holidays | B47: KSh 999 | C47: KSh 2,000 | D47: 0.5
A48: 60W Hot Melt Glue Sprayer - Efficient And Stable Glue Dispensing | B48: KSh 1,190 | C48: KSh 1,785 | D48: 0.33
...

Sheet Cleaned data
A1: Product | B1: Current price | C1: old price | D1: Discount | E1: Review | F1: Rating | G1: discount amount | H1: rating category | I1: discount category | J1: price category
A2: LASA Aluminum Folding Truck Hand Cart - 68kg Max | B2: 2025 | C2: 3971 | D2: 0.49 | E2: 3 | F2: 5 | G2: =C2-B2 -> 1946 | H2: =IF(F2="","Missing",IF(F2>=4,"Excellent",IF(F2>=3,"Good",IF(F2>=2,"Average","Poor")))) -> Excellent | I2: =IF(D2="","Missing",IF(D2<=20%,"Low",IF(D2<=40%,"Moderate",IF(D2<=60%,"High","Very High")))) -> High | J2: =IF(B2="","Missing",IF(B2<1000,"Budget",IF(B2<3000,"Mid-Range",IF(B2<5000,"Premium","High-End")))) -> Mid-Range
A3: Anti-Skid Absorbent Insulation Coaster For Home Office | B3: 332 | C3: 684 | D3: 0.51 | E3: 2 | F3: 5 | G3: =C3-B3 -> 352 | H3: =IF(F3="","Missing",IF(F3>=4,"Excellent",IF(F3>=3,"Good",IF(F3>=2,"Average","Poor")))) -> Excellent | I3: =IF(D3="","Missing",IF(D3<=20%,"Low",IF(D3<=40%,"Moderate",IF(D3<=60%,"High","Very High")))) -> High | J3: =IF(B3="","Missing",IF(B3<1000,"Budget",IF(B3<3000,"Mid-Range",IF(B3<5000,"Premium","High-End")))) -> Budget
A4: Peacock Throw Pillow Cushion Case For Home Car | B4: 195 | C4: 360 | D4: 0.46 | E4: 2 | F4: 5 | G4: =C4-B4 -> 165 | H4: =IF(F4="","Missing",IF(F4>=4,"Excellent",IF(F4>=3,"Good",IF(F4>=2,"Average","Poor")))) -> Excellent | I4: =IF(D4="","Missing",IF(D4<=20%,"Low",IF(D4<=40%,"Moderate",IF(D4<=60%,"High","Very High")))) -> High | J4: =IF(B4="","Missing",IF(B4<1000,"Budget",IF(B4<3000,"Mid-Range",IF(B4<5000,"Premium","High-End")))) -> Budget
A5: Classic Black Cat Cotton Hemp Pillow Case For Home Car | B5: 171 | C5: 360 | D5: 0.53 | E5: 2 | F5: 5 | G5: =C5-B5 -> 189 | H5: =IF(F5="","Missing",IF(F5>=4,"Excellent",IF(F5>=3,"Good",IF(F5>=2,"Average","Poor")))) -> Excellent | I5: =IF(D5="","Missing",IF(D5<=20%,"Low",IF(D5<=40%,"Moderate",IF(D5<=60%,"High","Very High")))) -> High | J5: =IF(B5="","Missing",IF(B5<1000,"Budget",IF(B5<3000,"Mid-Range",IF(B5<5000,"Premium","High-End")))) -> Budget
A6: DIY File Folder, Office Drawer File Holder, Pen Holder, Desktop Storage Rack | B6: 1620 | C6: 2690 | D6: 0.4 | E6: 1 | F6: 5 | G6: =C6-B6 -> 1070 | H6: =IF(F6="","Missing",IF(F6>=4,"Excellent",IF(F6>=3,"Good",IF(F6>=2,"Average","Poor")))) -> Excellent | I6: =IF(D6="","Missing",IF(D6<=20%,"Low",IF(D6<=40%,"Moderate",IF(D6<=60%,"High","Very High")))) -> Moderate | J6: =IF(B6="","Missing",IF(B6<1000,"Budget",IF(B6<3000,"Mid-Range",IF(B6<5000,"Premium","High-End")))) -> Mid-Range
A7: Bedroom Simple Floor Hanging Clothes Rack Single Pole Hat Rack - White | B7: 979 | C7: 1920 | D7: 0.49 | E7: 1 | F7: 5 | G7: =C7-B7 -> 941 | H7: =IF(F7="","Missing",IF(F7>=4,"Excellent",IF(F7>=3,"Good",IF(F7>=2,"Average","Poor")))) -> Excellent | I7: =IF(D7="","Missing",IF(D7<=20%,"Low",IF(D7<=40%,"Moderate",IF(D7<=60%,"High","Very High")))) -> High | J7: =IF(B7="","Missing",IF(B7<1000,"Budget",IF(B7<3000,"Mid-Range",IF(B7<5000,"Premium","High-End")))) -> Budget
A8: Konka Healty Electric Kettle, 24-hour Heat Preservation,1.5L,800W, White | B8: 3640 | C8: 4588 | D8: 0.21 | E8: 1 | F8: 5 | G8: =C8-B8 -> 948 | H8: =IF(F8="","Missing",IF(F8>=4,"Excellent",IF(F8>=3,"Good",IF(F8>=2,"Average","Poor")))) -> Excellent | I8: =IF(D8="","Missing",IF(D8<=20%,"Low",IF(D8<=40%,"Moderate",IF(D8<=60%,"High","Very High")))) -> Moderate | J8: =IF(B8="","Missing",IF(B8<1000,"Budget",IF(B8<3000,"Mid-Range",IF(B8<5000,"Premium","High-End")))) -> Premium
A9: 40cm Gold DIY Acrylic Wall Sticker Clock | B9: 552 | C9: 1035 | D9: 0.47 | E9: 12 | F9: 4.8 | G9: =C9-B9 -> 483 | H9: =IF(F9="","Missing",IF(F9>=4,"Excellent",IF(F9>=3,"Good",IF(F9>=2,"Average","Poor")))) -> Excellent | I9: =IF(D9="","Missing",IF(D9<=20%,"Low",IF(D9<=40%,"Moderate",IF(D9<=60%,"High","Very High")))) -> High | J9: =IF(B9="","Missing",IF(B9<1000,"Budget",IF(B9<3000,"Mid-Range",IF(B9<5000,"Premium","High-End")))) -> Budget
A10: Portable Home Small Air Humidifier 3-Speed Fan - Green | B10: 1740 | C10: 2356 | D10: 0.26 | E10: 5 | F10: 4.8 | G10: =C10-B10 -> 616 | H10: =IF(F10="","Missing",IF(F10>=4,"Excellent",IF(F10>=3,"Good",IF(F10>=2,"Average","Poor")))) -> Excellent | I10: =IF(D10="","Missing",IF(D10<=20%,"Low",IF(D10<=40%,"Moderate",IF(D10<=60%,"High","Very High")))) -> Moderate | J10: =IF(B10="","Missing",IF(B10<1000,"Budget",IF(B10<3000,"Mid-Range",IF(B10<5000,"Premium","High-End")))) -> Mid-Range
A11: LASA FOLDING TABLE SERVING STAND | B11: 1274 | C11: 2800 | D11: 0.55 | E11: 5 | F11: 4.8 | G11: =C11-B11 -> 1526 | H11: =IF(F11="","Missing",IF(F11>=4,"Excellent",IF(F11>=3,"Good",IF(F11>=2,"Average","Poor")))) -> Excellent | I11: =IF(D11="","Missing",IF(D11<=20%,"Low",IF(D11<=40%,"Moderate",IF(D11<=60%,"High","Very High")))) -> High | J11: =IF(B11="","Missing",IF(B11<1000,"Budget",IF(B11<3000,"Mid-Range",IF(B11<5000,"Premium","High-End")))) -> Mid-Range
A12: 100 Pcs Crochet Hook Tool Set Knitting Hook Set With Box | B12: 990 | C12: 1500 | D12: 0.34 | E12: 39 | F12: 4.7 | G12: =C12-B12 -> 510 | H12: =IF(F12="","Missing",IF(F12>=4,"Excellent",IF(F12>=3,"Good",IF(F12>=2,"Average","Poor")))) -> Excellent | I12: =IF(D12="","Missing",IF(D12<=20%,"Low",IF(D12<=40%,"Moderate",IF(D12<=60%,"High","Very High")))) -> Moderate | J12: =IF(B12="","Missing",IF(B12<1000,"Budget",IF(B12<3000,"Mid-Range",IF(B12<5000,"Premium","High-End")))) -> Budget
A13: 53Pcs/Set Yarn Knitting Crochet Hooks With Bag - Fortune Cat | B13: 1940 | C13: 2650 | D13: 0.27 | E13: 20 | F13: 4.7 | G13: =C13-B13 -> 710 | H13: =IF(F13="","Missing",IF(F13>=4,"Excellent",IF(F13>=3,"Good",IF(F13>=2,"Average","Poor")))) -> Excellent | I13: =IF(D13="","Missing",IF(D13<=20%,"Low",IF(D13<=40%,"Moderate",IF(D13<=60%,"High","Very High")))) -> Moderate | J13: =IF(B13="","Missing",IF(B13<1000,"Budget",IF(B13<3000,"Mid-Range",IF(B13<5000,"Premium","High-End")))) -> Mid-Range
... A58: Wall-mounted Sticker Punch-free Plug Fixer | B58: 450 | C58: 900 | D58: 0.5 | E58: 1 | F58: 2 | G58: =C58-B58 -> 450 | H58: =IF(F58="","Missing",IF(F58>=4,"Excellent",IF(F58>=3,"Good",IF(F58>=2,"Average","Poor")))) -> Average | I58: =IF(D58="","Missing",IF(D58<=20%,"Low",IF(D58<=40%,"Moderate",IF(D58<=60%,"High","Very High")))) -> High | J58: =IF(B58="","Missing",IF(B58<1000,"Budget",IF(B58<3000,"Mid-Range",IF(B58<5000,"Premium","High-End")))) -> Budget
A59: 4pcs Bathroom/Kitchen Towel Rack,Roll Paper Holder,Towel Bars,Hook | B59: 1860 | C59: 3220 | D59: 0.42 | G59: =C59-B59 -> 1360 | H59: =IF(F59="","Missing",IF(F59>=4,"Excellent",IF(F59>=3,"Good",IF(F59>=2,"Average","Poor")))) -> Missing | I59: =IF(D59="","Missing",IF(D59<=20%,"Low",IF(D59<=40%,"Moderate",IF(D59<=60%,"High","Very High")))) -> High | J59: =IF(B59="","Missing",IF(B59<1000,"Budget",IF(B59<3000,"Mid-Range",IF(B59<5000,"Premium","High-End")))) -> Mid-Range
A60: MultiFunctional Storage Rack Multi-layer Bookshelf | B60: 2200 | C60: 4080 | D60: 0.46 | G60: =C60-B60 -> 1880 | H60: =IF(F60="","Missing",IF(F60>=4,"Excellent",IF(F60>=3,"Good",IF(F60>=2,"Average","Poor")))) -> Missing | I60: =IF(D60="","Missing",IF(D60<=20%,"Low",IF(D60<=40%,"Moderate",IF(D60<=60%,"High","Very High")))) -> High | J60: =IF(B60="","Missing",IF(B60<1000,"Budget",IF(B60<3000,"Mid-Range",IF(B60<5000,"Premium","High-End")))) -> Mid-Range
A61: LASA Stainless Steel Double Wall Mount Soap Dispenser - 500ml | B61: 2750 | C61: 4471 | D61: 0.38 | G61: =C61-B61 -> 1721 | H61: =IF(F61="","Missing",IF(F61>=4,"Excellent",IF(F61>=3,"Good",IF(F61>=2,"Average","Poor")))) -> Missing | I61: =IF(D61="","Missing",IF(D61<=20%,"Low",IF(D61<=40%,"Moderate",IF(D61<=60%,"High","Very High")))) -> Moderate | J61: =IF(B61="","Missing",IF(B61<1000,"Budget",IF(B61<3000,"Mid-Range",IF(B61<5000,"Premium","High-End")))) -> Mid-Range
A62: 4M Float Switch Water Level Controller -Water Tank | B62: 475 | C62: 931 | D62: 0.49 | G62: =C62-B62 -> 456 | H62: =IF(F62="","Missing",IF(F62>=4,"Excellent",IF(F62>=3,"Good",IF(F62>=2,"Average","Poor")))) -> Missing | I62: =IF(D62="","Missing",IF(D62<=20%,"Low",IF(D62<=40%,"Moderate",IF(D62<=60%,"High","Very High")))) -> High | J62: =IF(B62="","Missing",IF(B62<1000,"Budget",IF(B62<3000,"Mid-Range",IF(B62<5000,"Premium","High-End")))) -> Budget
A63: Modern Sofa Throw Pillow Cover-45x45cm-Blue&Red | B63: 238 | C63: 476 | D63: 0.5 | G63: =C63-B63 -> 238 | H63: =IF(F63="","Missing",IF(F63>=4,"Excellent",IF(F63>=3,"Good",IF(F63>=2,"Average","Poor")))) -> Missing | I63: =IF(D63="","Missing",IF(D63<=20%,"Low",IF(D63<=40%,"Moderate",IF(D63<=60%,"High","Very High")))) -> High | J63: =IF(B63="","Missing",IF(B63<1000,"Budget",IF(B63<3000,"Mid-Range",IF(B63<5000,"Premium","High-End")))) -> Budget
A64: Balloon Insert, Birthday Party Balloon Set, PU Leather | B64: 610 | C64: 1060 | D64: 0.42 | G64: =C64-B64 -> 450 | H64: =IF(F64="","Missing",IF(F64>=4,"Excellent",IF(F64>=3,"Good",IF(F64>=2,"Average","Poor")))) -> Missing | I64: =IF(D64="","Missing",IF(D64<=20%,"Low",IF(D64<=40%,"Moderate",IF(D64<=60%,"High","Very High")))) -> High | J64: =IF(B64="","Missing",IF(B64<1000,"Budget",IF(B64<3000,"Mid-Range",IF(B64<5000,"Premium","High-End")))) -> Budget
A65: Shower Cap Wide Elastic Band Cover Reusable Bashroom Cap | B65: 2132 | C65: 2169 | D65: 0.02 | G65: =C65-B65 -> 37 | H65: =IF(F65="","Missing",IF(F65>=4,"Excellent",IF(F65>=3,"Good",IF(F65>=2,"Average","Poor")))) -> Missing | I65: =IF(D65="","Missing",IF(D65<=20%,"Low",IF(D65<=40%,"Moderate",IF(D65<=60%,"High","Very High")))) -> Low | J65: =IF(B65="","Missing",IF(B65<1000,"Budget",IF(B65<3000,"Mid-Range",IF(B65<5000,"Premium","High-End")))) -> Mid-Range
A66: Christmas Elk Fence Yard Lawn Decorations Cute For Holidays | B66: 999 | C66: 2000 | D66: 0.5 | G66: =C66-B66 -> 1001 | H66: =IF(F66="","Missing",IF(F66>=4,"Excellent",IF(F66>=3,"Good",IF(F66>=2,"Average","Poor")))) -> Missing | I66: =IF(D66="","Missing",IF(D66<=20%,"Low",IF(D66<=40%,"Moderate",IF(D66<=60%,"High","Very High")))) -> High | J66: =IF(B66="","Missing",IF(B66<1000,"Budget",IF(B66<3000,"Mid-Range",IF(B66<5000,"Premium","High-End")))) -> Budget
A67: 60W Hot Melt Glue Sprayer - Efficient And Stable Glue Dispensing | B67: 1190 | C67: 1785 | D67: 0.33 | G67: =C67-B67 -> 595 | H67: =IF(F67="","Missing",IF(F67>=4,"Excellent",IF(F67>=3,"Good",IF(F67>=2,"Average","Poor")))) -> Missing | I67: =IF(D67="","Missing",IF(D67<=20%,"Low",IF(D67<=40%,"Moderate",IF(D67<=60%,"High","Very High")))) -> Moderate | J67: =IF(B67="","Missing",IF(B67<1000,"Budget",IF(B67<3000,"Mid-Range",IF(B67<5000,"Premium","High-End")))) -> Mid-Range
A68: Car Phone Charging Stand | B68: 671 | C68: 1316 | D68: 0.49 | G68: =C68-B68 -> 645 | H68: =IF(F68="","Missing",IF(F68>=4,"Excellent",IF(F68>=3,"Good",IF(F68>=2,"Average","Poor")))) -> Missing | I68: =IF(D68="","Missing",IF(D68<=20%,"Low",IF(D68<=40%,"Moderate",IF(D68<=60%,"High","Very High")))) -> High | J68: =IF(B68="","Missing",IF(B68<1000,"Budget",IF(B68<3000,"Mid-Range",IF(B68<5000,"Premium","High-End")))) -> Budget
A69: 2pcs Solar Street Light Flood Light Outdoor | B69: 1200 | C69: 1950 | D69: 0.38 | G69: =C69-B69 -> 750 | H69: =IF(F69="","Missing",IF(F69>=4,"Excellent",IF(F69>=3,"Good",IF(F69>=2,"Average","Poor")))) -> Missing | I69: =IF(D69="","Missing",IF(D69<=20%,"Low",IF(D69<=40%,"Moderate",IF(D69<=60%,"High","Very High")))) -> Moderate | J69: =IF(B69="","Missing",IF(B69<1000,"Budget",IF(B69<3000,"Mid-Range",IF(B69<5000,"Premium","High-End")))) -> Mid-Range
A70: Creative Owl Shape Keychain Black | B70: 199 | C70: 504 | D70: 0.61 | G70: =C70-B70 -> 305 | H70: =IF(F70="","Missing",IF(F70>=4,"Excellent",IF(F70>=3,"Good",IF(F70>=2,"Average","Poor")))) -> Missing | I70: =IF(D70="","Missing",IF(D70<=20%,"Low",IF(D70<=40%,"Moderate",IF(D70<=60%,"High","Very High")))) -> Very High | J70: =IF(B70="","Missing",IF(B70<1000,"Budget",IF(B70<3000,"Mid-Range",IF(B70<5000,"Premium","High-End")))) -> Budget
... A110: Black Simple Water Cup Wine Coaster Anti Slip Absorbent | B110: 169 | C110: 320 | D110: 0.47 | G110: =C110-B110 -> 151 | H110: =IF(F110="","Missing",IF(F110>=4,"Excellent",IF(F110>=3,"Good",IF(F110>=2,"Average","Poor")))) -> Missing | I110: =IF(D110="","Missing",IF(D110<=20%,"Low",IF(D110<=40%,"Moderate",IF(D110<=60%,"High","Very High")))) -> High | J110: =IF(B110="","Missing",IF(B110<1000,"Budget",IF(B110<3000,"Mid-Range",IF(B110<5000,"Premium","High-End")))) -> Budget

Sheet cleaning log
A1: issue | B1: action taken | C1: reason
A2: duplicates | B2: Removed duplicate rows | C2: Avoid counting the same product more than once
A3: missing reviews and ratings | B3: kept blank | C3: should not be assumed to be 0
A4: Currency symbols/commas | B4: removed | C4: Convert prices to usable numbers
A5: Price ranges | B5: replaced with midpoint | C5: Need one numeric value for analysis
A6: rating format | B6: removed out of 5 | C6: Convert ratings to numeric values

Sheet Pivot tables 
A1: basic statistics | D1: discount v/s review
A3: total products | B3: =COUNTA('Cleaned data'!A2:A200) -> 109 | D3: discount category | E3: average review
A4: average current price | B4: =AVERAGE('Cleaned data'!B2:B200) -> 1208.2569 | D4: low | E4: =SUMIF('Cleaned data'!I2:I200,"Low",'Cleaned data'!E2:E200)/COUNTIFS('Cleaned data'!I2:I200,"Low",'Cleaned data'!E2:E200,">=0") -> 10
A5: average old price | B5: =AVERAGE('Cleaned data'!C2:C200) -> 1837.7523 | D5: moderate | E5: =SUMIF('Cleaned data'!I2:I200,"Moderate",'Cleaned data'!E2:E200)/COUNTIFS('Cleaned data'!I2:I200,"Moderate",'Cleaned data'!E2:E200,">=0") -> 15.409091
A6: average discount | B6: =AVERAGE('Cleaned data'!D2:D200) -> 0.36385321 | D6: high | E6: =SUMIF('Cleaned data'!I2:I200,"High",'Cleaned data'!E2:E200)/COUNTIFS('Cleaned data'!I2:I200,"High",'Cleaned data'!E2:E200,">=0") -> 11.133333
A7: average reviews | B7: =AVERAGE('Cleaned data'!E2:E200) -> 12.684211
A8: average rating | B8: =AVERAGE('Cleaned data'!F2:F200) -> 3.8894737
A9: lowest current price | B9: =MIN('Cleaned data'!B2:B200) -> 38
A10: highest current price | B10: =MAX('Cleaned data'!B2:B200) -> 3750
A11: lowest old price | B11: =MIN('Cleaned data'!C2:C200) -> 80
A12: highest old price | B12: =MAX('Cleaned data'!C2:C200) -> 6143
A14: total reviews | B14: =SUM('Cleaned data'!E2:E200) -> 723
A15: total discount amount | B15: =SUM('Cleaned data'!G2:G200) -> 68615
A17: price category distribution
A18: budget | B18: =COUNTIF('Cleaned data'!J2:J200,"Budget") -> 54
A19: mid range | B19: =COUNTIF('Cleaned data'!J2:J200,"Mid-Range") -> 52
A20: premium | B20: =COUNTIF('Cleaned data'!J2:J200,"Premium") -> 3
A21: high end | B21: =COUNTIF('Cleaned data'!J2:J200,"High-End") -> 0
A23: discount category distribution
A24: low | B24: =COUNTIF('Cleaned data'!I2:I200,"Low") -> 19
A25: moderate | B25: =COUNTIF('Cleaned data'!I2:I200,"Moderate") -> 31
A26: high | B26: =COUNTIF('Cleaned data'!I2:I200,"High") -> 57
A27: very high | B27: =COUNTIF('Cleaned data'!I2:I200,"Very High") -> 2
A29: rating category distribution
A30: excellent | B30: =COUNTIF('Cleaned data'!H2:H200,"Excellent") -> 36
A31: good | B31: =COUNTIF('Cleaned data'!H2:H200,"Good") -> 9
A32: average | B32: =COUNTIF('Cleaned data'!H2:H200,"Average") -> 12
A33: poor | B33: =COUNTIF('Cleaned data'!H2:H200,"Poor") -> 0
A34: missing | B34: =COUNTIF('Cleaned data'!H2:H200,"Missing") -> 52
A36: top 5 products by review
A37: product | B37: review
A38: 120W Cordless Vacuum Cleaners Handheld Electric Vacuum Cleaner | B38: 69
A39: 137 Pieces Cake Decorating Tool Set Baking Supplies | B39: 55
A40: Electronic Digital Display Vernier Caliper | B40: 49
A41: 3D Waterproof EVA Plastic Shower Curtain 1.8*2Mtrs | B41: 44
A42: 100 Pcs Crochet Hook Tool Set Knitting Hook Set With Box | B42: 39
A44: top 5 products by rating
A45: product | B45: rating
A46: LASA Aluminum Folding Truck Hand Cart - 68kg Max | B46: 5
A47: Anti-Skid Absorbent Insulation Coaster For Home Office | B47: 5
...

Sheet Dashboard 
A1: jumia product analysis dashboard
A3: total products | C3: average discount
A4: 109 | C4: 0.36
A6: current average price | C6: average rating
A7: 1208.26 | C7: 3.88
A10: price category distribution | B10: Column1
A11: budget | B11: 54
A12: mid range | B12: 52
A13: premium | B13: 3
A15: discount category distribution | B15: Column1
A16: low | B16: 19
A17: moderate | B17: 31
A18: high | B18: 57
A19: very high | B19: 2
